Workbook

Sheet ESG - Part 1
B2: ESG & Governance Scores | G2: Ownership Structure
B3: Metric | C3: Value | G3: Shareholder | H3: % Ownership
B4: Overall ESG Score (BESG ESG Score) | C4: 7.68 | G4: BlackRock Investment Management (UK) | H4: 0.0589
B5: Environmental Pillar Score | C5: 7.15 | G5: Capital Research and Management Company | H5: 0.0499
B6: Social Pillar Score | C6: 8.03 | G6: Massachusetts Financial Services Company | H6: 0.0499
B7: Governance Pillar Score | C7: 7.78
B8: Governance Disclosure Score | C8: 85.55
B9: Controversy / ESG Risk Score | C9: Not available
G10: Executive Compensation
B11: Board Structure | G11: Metric | H11: Value
B12: Metric | C12: Value
B13: Metric | C13: Value | G13: Total CEO remuneration (Debra Crew) | H13: £3,067
B14: Board size | C14: 10 directors | G14: Total CEO remuneration (Debra Crew) | H14: 3856
B15: Independent directors (% / count) | C15: 80% (8 of 10) | G15: Fixed pay | H15: £1,696 (£000)
B16: Female directors (% Women on Board) | C16: 0.7 | G16: Variable pay | H16: £1,371 (£000)
B17: CEO–Chair structure | C17: Separate roles (No CEO duality) | G17: Annual bonus payout | H17: 24.8% of maximum
B18: Board meeting attendance | C18: 98.36% (FY2024) | G18: Financial element of bonus | H18: 16% of maximum
B20: Committee Structure & Independence | G20: LTIP (Long-Term Incentive Plan) KPIs
B21: Committee | C21: Independence | G21: KPI | H21: Actual Value
B22: Audit Committee | C22: 100% independent | G22: LTIP vesting (Performance Shares) | H22: 0.589
B23: Remuneration Committee | C23: 100% independent | G23: LTIP vesting (Share Options) | H23: 0
B24: Nomination Committee | C24: 100% independent | G24: Relative TSR ranking | H24: 14th
B25: Sustainability / ESG Committee | C25: No dedicated committee | G25: Organic Net Sales Value growth | H25: 0.087
G26: PBET (Profit Before Exceptional Items & Tax) growth | H26: 0.069
G27: Carbon reduction (ESG KPI) | H27: 19.6% actual
G28: Water efficiency (ESG KPI) | H28: 4.2% actual
G29: Inclusion & diversity – female leaders | H29: 0.44

Sheet Inputs
A1: A. COMPANY & MARKET DATA
A2: Company Name | B2: Diageo plc | D2: All values in Bloomberg units (millions of GBP)
A3: Currency | B3: GBP | C3: All values in GBP millions
A4: Analysis Date | B4: 2024-12-05
A6: B. COST OF CAPITAL (GIVEN)
A7: WACC (%) | B7: 0.084
A8: Cost of Equity, r_e (%) (£m) | B8: 0.101
A9: Cost of Debt, r_d (%) (£m) | B9: 0.042
A10: Risk-Free Rate (%) | B10: 0.0443
A11: Beta (Levered) | B11: 0.78
A12: Corporate Tax Rate (%) | B12: 0.25
A14: C. VALUATION ASSUMPTIONS
A15: Terminal Growth Rate - Perpetuity (%) | B15: 0.02
A16: Projection Period (years) | B16: 10
A17: Discounting Convention | B17: End of period
A18: Inflation Assumption (%) | B18: 0.02
A19: FX Rate (GBP/USD) | B19: 1.27
A21: D. CAPITAL STRUCTURE (CURRENT)
A22: Market Value of Equity (£m) | B22: See Bloomberg 72% weight
A23: Market Value of Debt (£m) | B23: See Bloomberg 28% weight
A24: Total Capital (£m) | B24: N/A
A25: Weight of Equity (%) (£m) | B25: 0.72
A26: Weight of Debt (%) (£m) | B26: 0.28
A27: Check: Sum of Weights | B27: =B25+B26 -> 1
A29: A. PROJECT IDENTIFICATION
A30: Project Name | B30: Premium Ready-To-Drink (RTD) Expansion Project
A31: Project Location | B31: United Kingdom
A32: Project Description | B32: Capacity expansion + product innovation in RTD spirits
A34: B. PROJECT TIMELINE
A35: Project Life (years) | B35: 8
A37: C. INITIAL INVESTMENT (YEAR 0) (£m)
A38: Initial CAPEX (£m) | B38: 300
A39: Pre-Operating Costs | B39: 20
A40: Initial Working Capital Investment (£m) | B40: 30
A42: D. REVENUE ASSUMPTIONS (£m)
A43: Year 1 Revenue (£m) | B43: 150
A44: Revenue Growth Rate (Years 2–5) (%) (£m) | B44: 0.06
A45: Revenue Growth Rate (Years 6+) (%) (£m) | B45: 0.03
A46: Terminal Growth Rate (%) | B46: 0.02
A48: E. OPERATING COST ASSUMPTIONS
...

Sheet Hist_Financials
A1: All figures in GBP millions
A2: Line Item | B2: FY 2020 | C2: FY 2021 | D2: FY 2022 | E2: FY 2023 | F2: FY 2024 | G2: 5-Year Average
A3: INCOME STATEMENT
A4: Revenue (£m) | B4: 1175200 | C4: 1273300 | D4: 1543751.4 | E4: 1708670.7 | F4: 1609758.8 | G4: =AVERAGE(B4:F4) -> 1462136.2
A5: COGS (£m) | B5: 465400 | C5: 503800 | D5: 596175.8 | E5: 689037.8 | F5: 640996.7 | G5: =AVERAGE(B5:F5) -> 579082.06
A6: Gross Profit | B6: 709800 | C6: 769500 | D6: 947575.6 | E6: 1019632.9 | F6: 968762 | G6: =AVERAGE(B6:F6) -> 883054.1
A7: Operating Expenses (£m) | B7: 496600 | C7: 396700 | D7: 502795.2 | E7: 557614.4 | F7: 493196.6 | G7: =AVERAGE(B7:F7) -> 489381.24
A8: EBITDA (£m) | B8: =B6-B7+B9 -> 477800 | C8: =C6-C7+C9 -> 792800 | D8: =D6-D7+D9 -> 969622.8 | E8: =E6-E7+E9 -> 1031935.6 | F8: =F6-F7+F9 -> 991952.6 | G8: =AVERAGE(B8:F8) -> 852822.2
A9: EBITDA (£m) | B9: 264600 | C9: 420000 | D9: 524842.4 | E9: 569917.1 | F9: 516387.2 | G9: =AVERAGE(B9:F9) -> 459149.34
A10: Depreciation & Amortisation | B10: 49400 | C10: 44700 | D10: 80062 | E10: 107815.4 | F10: 39153.9 | G10: =AVERAGE(B10:F10) -> 64226.26
A11: EBIT (£m) | B11: 215200 | C11: 375300 | D11: 444780.4 | E11: 462101.7 | F11: 477233.2 | G11: =AVERAGE(B11:F11) -> 394923.06
A12: Interest Expense | B12: 53400 | C12: 47600 | D12: 49135.8 | E12: 77806.7 | F12: 56785.1 | G12: =AVERAGE(B12:F12) -> 56945.52
A13: Pre-Tax Income | B13: 204300 | C13: 370600 | D13: 437030 | E13: 469001.2 | F13: 433631.8 | G13: =AVERAGE(B13:F13) -> 382912.6
A14: Taxes | B14: 58900 | C14: 90700 | D14: 105194.2 | E14: 96676.4 | F14: 102769.1 | G14: =AVERAGE(B14:F14) -> 90847.94
A15: Net Income (£m) | B15: 140900 | C15: 266000 | D15: 322053.8 | E15: 369498.5 | F15: 307354.4 | G15: =AVERAGE(B15:F15) -> 281161.34
A17: BALANCE SHEET
A18: Total Assets (£m) | B18: 3330800 | C18: 3195300 | D18: 3628397.8 | E18: 3529647.7 | F18: 3597057.4 | G18: =AVERAGE(B18:F18) -> 3456240.6
A19: Total Liabilities (£m) | B19: 2486800 | C19: 2352200 | D19: 2683091.1 | E19: 2608839.3 | F19: 2642303.4 | G19: =AVERAGE(B19:F19) -> 2554646.8
A20: Total Equity (£m) | B20: 844000 | C20: 843100 | D20: 945306.7 | E20: 920808.4 | F20: 954754 | G20: =AVERAGE(B20:F20) -> 901593.82
A21: Short-Term Debt (£m) | B21: 199500 | C21: 186200 | D21: 151268.8 | E21: 168449.2 | F21: 228207.6 | G21: =AVERAGE(B21:F21) -> 186725.12
A22: Long-Term Debt (£m) | B22: 1479000 | C22: 1286500 | D22: 1440666.8 | E22: 1466577.5 | F22: 1472551.8 | G22: =AVERAGE(B22:F22) -> 1429059.2
A23: Cash & Cash Equivalents | B23: 339800 | C23: 287000 | D23: 251950.4 | E23: 176942.4 | F23: 117465.6 | G23: =AVERAGE(B23:F23) -> 234631.68
A25: FINANCIAL RATIOS & METRICS
A26: Net Debt (£m) | B26: =B21+B22-B23 -> 1338700 | C26: =C21+C22-C23 -> 1185700 | D26: =D21+D22-D23 -> 1339985.2 | E26: =E21+E22-E23 -> 1458084.3 | F26: =F21+F22-F23 -> 1583293.8 | G26: =AVERAGE(B26:F26) -> 1381152.7
A27: Debt/Assets (£m) | B27: =(B21+B22)/B18 -> 0.50393299 | C27: =(C21+C22)/C18 -> 0.46089569 | D27: =(D21+D22)/D18 -> 0.4387434 | E27: =(E21+E22)/E18 -> 0.4632266 | F27: =(F21+F22)/F18 -> 0.47281964 | G27: =AVERAGE(B27:F27) -> 0.46792367
A28: Debt/Equity (£m) | B28: =(B21+B22)/B20 -> 1.9887441 | C28: =(C21+C22)/C20 -> 1.7467679 | D28: =(D21+D22)/D20 -> 1.6840414 | E28: =(E21+E22)/E20 -> 1.7756427 | F28: =(F21+F22)/F20 -> 1.7813588 | G28: =AVERAGE(B28:F28) -> 1.795311
A29: Intangible Assets (£m) | B29: 1130000 | C29: 1076400 | D29: 1182639.4 | E29: 1140767.5 | F29: 1171808.3 | G29: =AVERAGE(B29:F29) -> 1140323
A30: Debt/Tangible Net Worth (£m) | B30: =(B21+B22)/(B20-B29) -> -5.8688811 | C30: =(C21+C22)/(C20-C29) -> -6.3124732 | D30: =(D21+D22)/(D20-D29) -> -6.7076117 | E30: =(E21+E22)/(E20-E29) -> -7.4333215 | F30: =(F21+F22)/(F20-F29) -> -7.8356402 | G30: =AVERAGE(B30:F30) -> -6.8315855
A31: Interest Coverage | B31: =B11/B12 -> 4.0299625 | C31: =C11/C12 -> 7.8844538 | D31: =D11/D12 -> 9.0520639 | E31: =E11/E12 -> 5.9390991 | F31: =F11/F12 -> 8.4041976 | G31: =AVERAGE(B31:F31) -> 7.0619554
A32: Check: Assets = Liabs + Equity (£m) | B32: =B18-(B19+B20) -> 0 | C32: =C18-(C19+C20) -> 0 | D32: =D18-(D19+D20) -> 0 | E32: =E18-(E19+E20) -> 0 | F32: =F18-(F19+F20) -> 0 | G32: =AVERAGE(B32:F32) -> 0

Sheet Hist_Ratios
A1: HISTORICAL RATIOS – DIAGEO PLC
A3: Ratio / Metric | B3: FY 2020 | C3: FY 2021 | D3: FY 2022 | E3: FY 2023 | F3: FY 2024 | G3: 5-Year Avg
A4: Revenue Growth (%) (£m) | B4: n/a | C4: =(Hist_Financials!C4-Hist_Financials!B4)/Hist_Financials!B4 -> 0.083475153 | D4: =(Hist_Financials!D4-Hist_Financials!C4)/Hist_Financials!C4 -> 0.21240195 | E4: =(Hist_Financials!E4-Hist_Financials!D4)/Hist_Financials!D4 -> 0.10683022 | F4: =(Hist_Financials!F4-Hist_Financials!E4)/Hist_Financials!E4 -> -0.057888217 | G4: =IFERROR(AVERAGE(B4:F4), "n/a") -> 0.086204776
A5: Gross Margin (%) | B5: =Hist_Financials!B6/Hist_Financials!B4 -> 0.6039823 | C5: =Hist_Financials!C6/Hist_Financials!C4 -> 0.60433519 | D5: =Hist_Financials!D6/Hist_Financials!D4 -> 0.6138136 | E5: =Hist_Financials!E6/Hist_Financials!E4 -> 0.59674044 | F5: =Hist_Financials!F6/Hist_Financials!F4 -> 0.60180569 | G5: =IFERROR(AVERAGE(B5:F5), "n/a") -> 0.60413544
A6: EBITDA Margin (%) (£m) | B6: =Hist_Financials!B9/Hist_Financials!B4 -> 0.22515317 | C6: =Hist_Financials!C9/Hist_Financials!C4 -> 0.32985157 | D6: =Hist_Financials!D9/Hist_Financials!D4 -> 0.33997857 | E6: =Hist_Financials!E9/Hist_Financials!E4 -> 0.33354414 | F6: =Hist_Financials!F9/Hist_Financials!F4 -> 0.32078545 | G6: =IFERROR(AVERAGE(B6:F6), "n/a") -> 0.30986258
A7: EBIT Margin (%) (£m) | B7: =Hist_Financials!B11/Hist_Financials!B4 -> 0.18311777 | C7: =Hist_Financials!C11/Hist_Financials!C4 -> 0.29474594 | D7: =Hist_Financials!D11/Hist_Financials!D4 -> 0.2881166 | E7: =Hist_Financials!E11/Hist_Financials!E4 -> 0.27044515 | F7: =Hist_Financials!F11/Hist_Financials!F4 -> 0.29646255 | G7: =IFERROR(AVERAGE(B7:F7), "n/a") -> 0.2665776
A8: Net Margin (%) | B8: =Hist_Financials!B15/Hist_Financials!B4 -> 0.11989449 | C8: =Hist_Financials!C15/Hist_Financials!C4 -> 0.20890599 | D8: =Hist_Financials!D15/Hist_Financials!D4 -> 0.20861766 | E8: =Hist_Financials!E15/Hist_Financials!E4 -> 0.2162491 | F8: =Hist_Financials!F15/Hist_Financials!F4 -> 0.19093196 | G8: =IFERROR(AVERAGE(B8:F8), "n/a") -> 0.18891984
A9: Effective Tax Rate (%) | B9: =IF(Hist_Financials!B13<=0,"",Hist_Financials!B14/Hist_Financials!B13) -> 0.28830152 | C9: =IF(Hist_Financials!C13<=0,"",Hist_Financials!C14/Hist_Financials!C13) -> 0.24473826 | D9: =IF(Hist_Financials!D13<=0,"",Hist_Financials!D14/Hist_Financials!D13) -> 0.24070247 | E9: =IF(Hist_Financials!E13<=0,"",Hist_Financials!E14/Hist_Financials!E13) -> 0.20613252 | F9: =IF(Hist_Financials!F13<=0,"",Hist_Financials!F14/Hist_Financials!F13) -> 0.23699623 | G9: =IFERROR(AVERAGE(B9:F9), "n/a") -> 0.2433742
A11: Total Debt (GBP) (£m) | B11: =Hist_Financials!B21+Hist_Financials!B22 -> 1678500 | C11: =Hist_Financials!C21+Hist_Financials!C22 -> 1472700 | D11: =Hist_Financials!D21+Hist_Financials!D22 -> 1591935.6 | E11: =Hist_Financials!E21+Hist_Financials!E22 -> 1635026.7 | F11: =Hist_Financials!F21+Hist_Financials!F22 -> 1700759.4 | G11: =IFERROR(AVERAGE(B11:F11), "n/a") -> 1615784.3
A12: Net Debt (GBP) (£m) | B12: =(Hist_Financials!B21+Hist_Financials!B22)-Hist_Financials!B23 -> 1338700 | C12: =(Hist_Financials!C21+Hist_Financials!C22)-Hist_Financials!C23 -> 1185700 | D12: =(Hist_Financials!D21+Hist_Financials!D22)-Hist_Financials!D23 -> 1339985.2 | E12: =(Hist_Financials!E21+Hist_Financials!E22)-Hist_Financials!E23 -> 1458084.3 | F12: =(Hist_Financials!F21+Hist_Financials!F22)-Hist_Financials!F23 -> 1583293.8 | G12: =IFERROR(AVERAGE(B12:F12), "n/a") -> 1381152.7
A13: Debt / Assets (%) (£m) | B13: =(Hist_Financials!B21+Hist_Financials!B22)/Hist_Financials!B18 -> 0.50393299 | C13: =(Hist_Financials!C21+Hist_Financials!C22)/Hist_Financials!C18 -> 0.46089569 | D13: =(Hist_Financials!D21+Hist_Financials!D22)/Hist_Financials!D18 -> 0.4387434 | E13: =(Hist_Financials!E21+Hist_Financials!E22)/Hist_Financials!E18 -> 0.4632266 | F13: =(Hist_Financials!F21+Hist_Financials!F22)/Hist_Financials!F18 -> 0.47281964 | G13: =IFERROR(AVERAGE(B13:F13), "n/a") -> 0.46792367
A14: Debt / Equity (x) (£m) | B14: =IF(Hist_Financials!B20<=0,"",(Hist_Financials!B21+Hist_Financials!B22)/Hist_Financials!B20) -> 1.9887441 | C14: =IF(Hist_Financials!C20<=0,"",(Hist_Financials!C21+Hist_Financials!C22)/Hist_Financials!C20) -> 1.7467679 | D14: =IF(Hist_Financials!D20<=0,"",(Hist_Financials!D21+Hist_Financials!D22)/Hist_Financials!D20) -> 1.6840414 | E14: =IF(Hist_Financials!E20<=0,"",(Hist_Financials!E21+Hist_Financials!E22)/Hist_Financials!E20) -> 1.7756427 | F14: =IF(Hist_Financials!F20<=0,"",(Hist_Financials!F21+Hist_Financials!F22)/Hist_Financials!F20) -> 1.7813588 | G14: =IFERROR(AVERAGE(B14:F14), "n/a") -> 1.795311
A15: Debt / Tangible Net Worth (x) (£m) | B15: =IF((Hist_Financials!B20-Hist_Financials!B29)<=0,"",(Hist_Financials!B21+Hist_Financials!B22)/(Hist_Financials!B20-Hist_Financials!B29)) | C15: =IF((Hist_Financials!C20-Hist_Financials!C29)<=0,"",(Hist_Financials!C21+Hist_Financials!C22)/(Hist_Financials!C20-Hist_Financials!C29)) | D15: =IF((Hist_Financials!D20-Hist_Financials!D29)<=0,"",(Hist_Financials!D21+Hist_Financials!D22)/(Hist_Financials!D20-Hist_Financials!D29)) | E15: =IF((Hist_Financials!E20-Hist_Financials!E29)<=0,"",(Hist_Financials!E21+Hist_Financials!E22)/(Hist_Financials!E20-Hist_Financials!E29)) | F15: =IF((Hist_Financials!F20-Hist_Financials!F29)<=0,"",(Hist_Financials!F21+Hist_Financials!F22)/(Hist_Financials!F20-Hist_Financials!F29)) | G15: =IFERROR(AVERAGE(B15:F15), "n/a") -> n/a
A16: Net Debt / EBITDA (x) (£m) | B16: =IF(Hist_Financials!B9<=0,"",((Hist_Financials!B21+Hist_Financials!B22)-Hist_Financials!B23)/Hist_Financials!B9) -> 5.0593348 | C16: =IF(Hist_Financials!C9<=0,"",((Hist_Financials!C21+Hist_Financials!C22)-Hist_Financials!C23)/Hist_Financials!C9) -> 2.8230952 | D16: =IF(Hist_Financials!D9<=0,"",((Hist_Financials!D21+Hist_Financials!D22)-Hist_Financials!D23)/Hist_Financials!D9) -> 2.5531192 | E16: =IF(Hist_Financials!E9<=0,"",((Hist_Financials!E21+Hist_Financials!E22)-Hist_Financials!E23)/Hist_Financials!E9) -> 2.5584147 | F16: =IF(Hist_Financials!F9<=0,"",((Hist_Financials!F21+Hist_Financials!F22)-Hist_Financials!F23)/Hist_Financials!F9) -> 3.0660981 | G16: =IFERROR(AVERAGE(B16:F16), "n/a") -> 3.2120124
A17: Interest Coverage (x) | B17: =IF(Hist_Financials!B12=0,"",ABS(Hist_Financials!B11/Hist_Financials!B12)) -> 4.0299625 | C17: =IF(Hist_Financials!C12=0,"",ABS(Hist_Financials!C11/Hist_Financials!C12)) -> 7.8844538 | D17: =IF(Hist_Financials!D12=0,"",ABS(Hist_Financials!D11/Hist_Financials!D12)) -> 9.0520639 | E17: =IF(Hist_Financials!E12=0,"",ABS(Hist_Financials!E11/Hist_Financials!E12)) -> 5.9390991 | F17: =IF(Hist_Financials!F12=0,"",ABS(Hist_Financials!F11/Hist_Financials!F12)) -> 8.4041976 | G17: =IFERROR(AVERAGE(B17:F17), "n/a") -> 7.0619554
A19: Return on Assets (ROA) (%) (£m) | B19: =Hist_Financials!B15/Hist_Financials!B18 -> 0.04230215 | C19: =Hist_Financials!C15/Hist_Financials!C18 -> 0.083247269 | D19: =Hist_Financials!D15/Hist_Financials!D18 -> 0.088759231 | E19: =Hist_Financials!E15/Hist_Financials!E18 -> 0.10468424 | F19: =Hist_Financials!F15/Hist_Financials!F18 -> 0.085446065 | G19: =IFERROR(AVERAGE(B19:F19), "n/a") -> 0.080887792
A20: Return on Equity (ROE) (%) (£m) | B20: =IF(Hist_Financials!B20<=0,"",Hist_Financials!B15/Hist_Financials!B20) -> 0.16694313 | C20: =IF(Hist_Financials!C20<=0,"",Hist_Financials!C15/Hist_Financials!C20) -> 0.31550231 | D20: =IF(Hist_Financials!D20<=0,"",Hist_Financials!D15/Hist_Financials!D20) -> 0.3406871 | E20: =IF(Hist_Financials!E20<=0,"",Hist_Financials!E15/Hist_Financials!E20) -> 0.4012762 | F20: =IF(Hist_Financials!F20<=0,"",Hist_Financials!F15/Hist_Financials!F20) -> 0.32191999 | G20: =IFERROR(AVERAGE(B20:F20), "n/a") -> 0.30926575
A21: Asset Turnover (x) (£m) | B21: =Hist_Financials!B4/Hist_Financials!B18 -> 0.35282815 | C21: =Hist_Financials!C4/Hist_Financials!C18 -> 0.39849153 | D21: =Hist_Financials!D4/Hist_Financials!D18 -> 0.42546366 | E21: =Hist_Financials!E4/Hist_Financials!E18 -> 0.484091 | F21: =Hist_Financials!F4/Hist_Financials!F18 -> 0.44752102 | G21: =IFERROR(AVERAGE(B21:F21), "n/a") -> 0.42167907
A22: Equity Multiplier (x) (£m) | B22: =IF(Hist_Financials!B20<=0,"",Hist_Financials!B18/Hist_Financials!B20) -> 3.9464455 | C22: =IF(Hist_Financials!C20<=0,"",Hist_Financials!C18/Hist_Financials!C20) -> 3.7899419 | D22: =IF(Hist_Financials!D20<=0,"",Hist_Financials!D18/Hist_Financials!D20) -> 3.8383287 | E22: =IF(Hist_Financials!E20<=0,"",Hist_Financials!E18/Hist_Financials!E20) -> 3.8332054 | F22: =IF(Hist_Financials!F20<=0,"",Hist_Financials!F18/Hist_Financials!F20) -> 3.7675227 | G22: =IFERROR(AVERAGE(B22:F22), "n/a") -> 3.8350888

Sheet Capital_Structure
A1: CAPITAL STRUCTURE & WACC
A4: Official Bloomberg Capital Structure
A5: Weight of Equity (Target) (£m) | B5: 0.72
A6: Weight of Debt (Target) (£m) | B6: 0.28
A8: Cost of Capital Inputs (Reference Only)
A9: Cost of Equity (r_e) (£m) | B9: =Inputs!B8 -> 0.101
A10: Cost of Debt (r_d) (£m) | B10: =Inputs!B9 -> 0.042
A11: Risk-Free Rate (r_f) | B11: =Inputs!B10 -> 0.0443
A12: Beta (Levered) | B12: =Inputs!B11 -> 0.78
A13: Corporate Tax Rate (t) | B13: =Inputs!B12 -> 0.25
A15: WACC Verification
A16: Recomputed WACC | B16: =Inputs!B7 -> 0.084
A17: Difference | B17: 0

Sheet Project_Assumptions
A1: A. PROJECT IDENTIFICATION
A2: Project Name | B2: Premium RTD Expansion
A3: Project Location | B3: United Kingdom
A4: Project Description | B4: Capacity expansion + RTD product innovation
A5: Analysis Date | B5: 2024-12-05
A7: B. PROJECT TIMELINE
A8: Project Life (years) | B8: 8
A9: Start Year | B9: 2025
A10: First Operating Year | B10: 2026
A11: Final Operating Year | B11: 2033
A13: C. INITIAL INVESTMENT (YEAR 0) (£m)
A14: Initial CAPEX (£m) | B14: 300
A15: Pre-Operating Costs | B15: 20
A16: Initial Working Capital Investment (£m) | B16: 30
A17: Total Initial Investment (£m) | B17: =SUM(B14:B16) -> 350
A19: D. REVENUE ASSUMPTIONS (£m)
A20: Year 1 Revenue (£m) | B20: 160
A21: Revenue Growth Rate (Years 2-4) (£m) | B21: 0.07
A22: Revenue Growth Rate (Years 5-6) (£m) | B22: 0.04
A23: Terminal Growth Rate | B23: 0.02
A25: E. OPERATING COST ASSUMPTIONS
A26: COGS (% of Revenue) (£m) | B26: 0.4
A27: Operating Expenses (% of Revenue) (£m) | B27: 0.18
A29: F. DEPRECIATION
A30: Depreciation Method | B30: Straight-line
A31: Depreciable CAPEX (£m) | B31: 300
A32: Depreciation Period (years) | B32: 8
A33: Annual Depreciation | B33: 37.5
A34: Corporate Tax Rate | B34: 0.25
A36: G. MAINTENANCE CAPEX (£m)
A37: Maintenance CAPEX (% of Revenue) (£m) | B37: 0.02
A38: Maintenance CAPEX (Fixed) (£m) | B38: 0
A40: H. WORKING CAPITAL
A41: Net Working Capital (% of Revenue) (£m) | B41: 0.15
A42: NWC Recovery at Project End | B42: Yes
A44: I. TERMINAL VALUE ASSUMPTIONS (£m)
A45: Terminal Value Method (£m) | B45: Perpetuity Growth
A46: Salvage Value (£m) | B46: 20
A47: Terminal Growth Rate (Checks) | B47: 0.02
A49: J. FINANCING (OPTIONAL FOR APV) (£m) | B49: 0.36
...

Sheet Project_FCF
A1: Period | B1: Year 0 | C1: Year 1 | D1: Year 2 | E1: Year 3 | F1: Year 4 | G1: Year 5 | H1: Year 6 | I1: Year 7 | J1: Year 8
A2: Revenue (£m) | B2: 0 | C2: =Project_Assumptions!$B$20 -> 160 | D2: =C2*(1+Project_Assumptions!$B$21) -> 171.2 | E2: =D2*(1+Project_Assumptions!$B$21) -> 183.184 | F2: =E2*(1+Project_Assumptions!$B$21) -> 196.00688 | G2: =F2*(1+Project_Assumptions!$B$22) -> 203.84716 | H2: =G2*(1+Project_Assumptions!$B$22) -> 212.00104 | I2: =H2*(1+Project_Assumptions!$B$23) -> 216.24106 | J2: =I2*(1+Project_Assumptions!$B$23) -> 220.56588
A3: COGS (£m) | B3: 0 | C3: =-C2*Project_Assumptions!$B$26 -> -64 | D3: =-D2*Project_Assumptions!$B$26 -> -68.48 | E3: =-E2*Project_Assumptions!$B$26 -> -73.2736 | F3: =-F2*Project_Assumptions!$B$26 -> -78.402752 | G3: =-G2*Project_Assumptions!$B$26 -> -81.538862 | H3: =-H2*Project_Assumptions!$B$26 -> -84.800417 | I3: =-I2*Project_Assumptions!$B$26 -> -86.496425 | J3: =-J2*Project_Assumptions!$B$26 -> -88.226353
A4: Operating Expenses (£m) | B4: 0 | C4: =-C2*Project_Assumptions!$B$27 -> -28.8 | D4: =-D2*Project_Assumptions!$B$27 -> -30.816 | E4: =-E2*Project_Assumptions!$B$27 -> -32.97312 | F4: =-F2*Project_Assumptions!$B$27 -> -35.281238 | G4: =-G2*Project_Assumptions!$B$27 -> -36.692488 | H4: =-H2*Project_Assumptions!$B$27 -> -38.160187 | I4: =-I2*Project_Assumptions!$B$27 -> -38.923391 | J4: =-J2*Project_Assumptions!$B$27 -> -39.701859
A5: Total Operating Costs | B5: 0 | C5: =C3+C4 -> -92.8 | D5: =D3+D4 -> -99.296 | E5: =E3+E4 -> -106.24672 | F5: =F3+F4 -> -113.68399 | G5: =G3+G4 -> -118.23135 | H5: =H3+H4 -> -122.9606 | I5: =I3+I4 -> -125.41982 | J5: =J3+J4 -> -127.92821
A6: EBITDA (£m) | B6: 0 | C6: =C2+C5 -> 67.2 | D6: =D2+D5 -> 71.904 | E6: =E2+E5 -> 76.93728 | F6: =F2+F5 -> 82.32289 | G6: =G2+G5 -> 85.615805 | H6: =H2+H5 -> 89.040437 | I6: =I2+I5 -> 90.821246 | J6: =J2+J5 -> 92.637671
A7: Depreciation | B7: 0 | C7: =-Project_Assumptions!$B$33 -> -37.5 | D7: =-Project_Assumptions!$B$33 -> -37.5 | E7: =-Project_Assumptions!$B$33 -> -37.5 | F7: =-Project_Assumptions!$B$33 -> -37.5 | G7: =-Project_Assumptions!$B$33 -> -37.5 | H7: =-Project_Assumptions!$B$33 -> -37.5 | I7: =-Project_Assumptions!$B$33 -> -37.5 | J7: =-Project_Assumptions!$B$33 -> -37.5
A8: EBIT (£m) | B8: 0 | C8: =C6+C7 -> 29.7 | D8: =D6+D7 -> 34.404 | E8: =E6+E7 -> 39.43728 | F8: =F6+F7 -> 44.82289 | G8: =G6+G7 -> 48.115805 | H8: =H6+H7 -> 51.540437 | I8: =I6+I7 -> 53.321246 | J8: =J6+J7 -> 55.137671
A9: Tax Expense | B9: 0 | C9: =-MAX(C8,0)*Project_Assumptions!$B$34 -> -7.425 | D9: =-MAX(D8,0)*Project_Assumptions!$B$34 -> -8.601 | E9: =-MAX(E8,0)*Project_Assumptions!$B$34 -> -9.85932 | F9: =-MAX(F8,0)*Project_Assumptions!$B$34 -> -11.205722 | G9: =-MAX(G8,0)*Project_Assumptions!$B$34 -> -12.028951 | H9: =-MAX(H8,0)*Project_Assumptions!$B$34 -> -12.885109 | I9: =-MAX(I8,0)*Project_Assumptions!$B$34 -> -13.330312 | J9: =-MAX(J8,0)*Project_Assumptions!$B$34 -> -13.784418
A10: NOPAT | B10: 0 | C10: =C8+C9 -> 22.275 | D10: =D8+D9 -> 25.803 | E10: =E8+E9 -> 29.57796 | F10: =F8+F9 -> 33.617167 | G10: =G8+G9 -> 36.086854 | H10: =H8+H9 -> 38.655328 | I10: =I8+I9 -> 39.990935 | J10: =J8+J9 -> 41.353253
A13: Add: Depreciation | B13: 0 | C13: =Project_Assumptions!$B$33 -> 37.5 | D13: =Project_Assumptions!$B$33 -> 37.5 | E13: =Project_Assumptions!$B$33 -> 37.5 | F13: =Project_Assumptions!$B$33 -> 37.5 | G13: =Project_Assumptions!$B$33 -> 37.5 | H13: =Project_Assumptions!$B$33 -> 37.5 | I13: =Project_Assumptions!$B$33 -> 37.5 | J13: =Project_Assumptions!$B$33 -> 37.5
A14: Less: CAPEX (£m) | B14: =-Project_Assumptions!$B$17 -> -350 | C14: =-C2*Project_Assumptions!$B$37 -> -3.2 | D14: =-D2*Project_Assumptions!$B$37 -> -3.424 | E14: =-E2*Project_Assumptions!$B$37 -> -3.66368 | F14: =-F2*Project_Assumptions!$B$37 -> -3.9201376 | G14: =-G2*Project_Assumptions!$B$37 -> -4.0769431 | H14: =-H2*Project_Assumptions!$B$37 -> -4.2400208 | I14: =-I2*Project_Assumptions!$B$37 -> -4.3248212 | J14: =-J2*Project_Assumptions!$B$37 -> -4.4113177
A15: NWC Balance (Ref Only) | B15: 0 | C15: =C2*Project_Assumptions!$B$41 -> 24 | D15: =D2*Project_Assumptions!$B$41 -> 25.68 | E15: =E2*Project_Assumptions!$B$41 -> 27.4776 | F15: =F2*Project_Assumptions!$B$41 -> 29.401032 | G15: =G2*Project_Assumptions!$B$41 -> 30.577073 | H15: =H2*Project_Assumptions!$B$41 -> 31.800156 | I15: =I2*Project_Assumptions!$B$41 -> 32.436159 | J15: =IF(Project_Assumptions!$B$42="Yes",0,J2*Project_Assumptions!$B$41) -> 0
A16: Less: Change in NWC | B16: 0 | C16: =C15-B15 -> 24 | D16: =D15-C15 -> 1.68 | E16: =E15-D15 -> 1.7976 | F16: =F15-E15 -> 1.923432 | G16: =G15-F15 -> 1.1760413 | H16: =H15-G15 -> 1.2230829 | I16: =I15-H15 -> 0.63600312 | J16: =IF(Project_Assumptions!$B$42="Yes",-I15,J15-I15) -> -32.436159
A17: Terminal Value (£m) | B17: 0 | C17: 0 | D17: 0 | E17: 0 | F17: 0 | G17: 0 | H17: 0 | I17: 0 | J17: =(J10+J13+J14-J16)*(1+Inputs!$B$15)/(Inputs!$B$7-Inputs!$B$15) -> 1703.3696
A18: Free Cash Flow (FCFF) (£m) | B18: =B10+B13+B14-B16+B17 -> -350 | C18: =C10+C13+C14-C16+C17 -> 32.575 | D18: =D10+D13+D14-D16+D17 -> 58.199 | E18: =E10+E13+E14-E16+E17 -> 61.61668 | F18: =F10+F13+F14-F16+F17 -> 65.273598 | G18: =G10+G13+G14-G16+G17 -> 68.33387 | H18: =H10+H13+H14-H16+H17 -> 70.692224 | I18: =I10+I13+I14-I16+I17 -> 72.53011 | J18: =J10+J13+J14-J16+J17 -> 1810.2477

Sheet Val_WACC
A1: VALUATION: WACC METHOD
A2: Method: Discounts total project cash flows (FCFF + Terminal Value) at WACC to get Enterprise Value (£m)
A4: Year | B4: 0 | C4: 1 | D4: 2 | E4: 3 | F4: 4 | G4: 5 | H4: 6 | I4: 7 | J4: 8
A5: A. PROJECT CASH FLOWS (£m)
A6: Total Project Cash Flow (£m) | B6: =Project_FCF!B18 -> -350 | C6: =Project_FCF!C18 -> 32.575 | D6: =Project_FCF!D18 -> 58.199 | E6: =Project_FCF!E18 -> 61.61668 | F6: =Project_FCF!F18 -> 65.273598 | G6: =Project_FCF!G18 -> 68.33387 | H6: =Project_FCF!H18 -> 70.692224 | I6: =Project_FCF!I18 -> 72.53011 | J6: =Project_FCF!J18 -> 1810.2477
B7: =Project_FCF!B18 -> -350 | C7: =Project_FCF!C18 -> 32.575 | D7: =Project_FCF!D18 -> 58.199 | E7: =Project_FCF!E18 -> 61.61668 | F7: =Project_FCF!F18 -> 65.273598 | G7: =Project_FCF!G18 -> 68.33387 | H7: =Project_FCF!H18 -> 70.692224 | I7: =Project_FCF!I18 -> 72.53011 | J7: =Project_FCF!J18 -> 1810.2477
A9: B. DISCOUNTING AT WACC
A10: Discount Factor | B10: =1 -> 1 | C10: =1/(1+Inputs!$B$7)^1 -> 0.92250923 | D10: =1/(1+Inputs!$B$7)^2 -> 0.85102327 | E10: =1/(1+Inputs!$B$7)^3 -> 0.78507682 | F10: =1/(1+Inputs!$B$7)^4 -> 0.72424061 | G10: =1/(1+Inputs!$B$7)^5 -> 0.66811864 | H10: =1/(1+Inputs!$B$7)^6 -> 0.61634561 | I10: =1/(1+Inputs!$B$7)^7 -> 0.56858451 | J10: =1/(1+Inputs!$B$7)^8 -> 0.52452446
A11: PV of Cash Flow (£m) | B11: =B7*B10 -> -350 | C11: =C7*C10 -> 30.050738 | D11: =D7*D10 -> 49.528703 | E11: =E7*E10 -> 48.373827 | F11: =F7*F10 -> 47.27379 | G11: =G7*G10 -> 45.655132 | H11: =H7*H10 -> 43.570842 | I11: =I7*I10 -> 41.239497 | J11: =J7*J10 -> 949.51921
A14: C. VALUATION RESULTS
A16: Enterprise Value / Project NPV (£m) | B16: =SUM(B11:J11) -> 905.21174
A18: Project IRR (%) | B18: =IRR(B7:J7) -> 0.31594841
A21: D. ASSUMPTIONS USED
A22: WACC | B22: =Inputs!B7 -> 0.084
A23: Tax Rate | B23: =Inputs!B12 -> 0.25

Sheet Val_APV
A1: VALUATION: ADJUSTED PRESENT VALUE (APV) METHOD (£m)
A2: Method: APV = Base-Case NPV (at WACC) + PV of Tax Shields (at r_d) (£m)
A4: Year | B4: 0 | C4: 1 | D4: 2 | E4: 3 | F4: 4 | G4: 5 | H4: 6 | I4: 7 | J4: 8
A5: A. BASE-CASE VALUATION (UNLEVERED)
A6: Total Project Cash Flow (£m) | B6: =Project_FCF!B18 -> -350 | C6: =Project_FCF!C18 -> 32.575 | D6: =Project_FCF!D18 -> 58.199 | E6: =Project_FCF!E18 -> 61.61668 | F6: =Project_FCF!F18 -> 65.273598 | G6: =Project_FCF!G18 -> 68.33387 | H6: =Project_FCF!H18 -> 70.692224 | I6: =Project_FCF!I18 -> 72.53011 | J6: =Project_FCF!J18 -> 1810.2477
A7: Discount Factor (WACC) | B7: =1 -> 1 | C7: =1/(1+Inputs!$B$7)^1 -> 0.92250923 | D7: =1/(1+Inputs!$B$7)^2 -> 0.85102327 | E7: =1/(1+Inputs!$B$7)^3 -> 0.78507682 | F7: =1/(1+Inputs!$B$7)^4 -> 0.72424061 | G7: =1/(1+Inputs!$B$7)^5 -> 0.66811864 | H7: =1/(1+Inputs!$B$7)^6 -> 0.61634561 | I7: =1/(1+Inputs!$B$7)^7 -> 0.56858451 | J7: =1/(1+Inputs!$B$7)^8 -> 0.52452446
A8: PV of Cash Flow (£m) | B8: =B6*B7 -> -350 | C8: =C6*C7 -> 30.050738 | D8: =D6*D7 -> 49.528703 | E8: =E6*E7 -> 48.373827 | F8: =F6*F7 -> 47.27379 | G8: =G6*G7 -> 45.655132 | H8: =H6*H7 -> 43.570842 | I8: =I6*I7 -> 41.239497 | J8: =J6*J7 -> 949.51921
A10: Base-Case Project PV (£m) | B10: =SUM(B8:J8) -> 905.21174
A13: B. TAX SHIELDS FROM PROJECT DEBT (£m)
A14: Project Debt (£m) | B14: =Project_Assumptions!$B$50*Project_Assumptions!$B$17 -> 52.5 | C14: =Project_Assumptions!$B$50*Project_Assumptions!$B$17 -> 52.5 | D14: =Project_Assumptions!$B$50*Project_Assumptions!$B$17 -> 52.5 | E14: =Project_Assumptions!$B$50*Project_Assumptions!$B$17 -> 52.5 | F14: =Project_Assumptions!$B$50*Project_Assumptions!$B$17 -> 52.5 | G14: =Project_Assumptions!$B$50*Project_Assumptions!$B$17 -> 52.5 | H14: =Project_Assumptions!$B$50*Project_Assumptions!$B$17 -> 52.5 | I14: =Project_Assumptions!$B$50*Project_Assumptions!$B$17 -> 52.5 | J14: =Project_Assumptions!$B$50*Project_Assumptions!$B$17 -> 52.5
A15: Interest Expense (£m) | B15: 0 | C15: =C14*Project_Assumptions!$B$51 -> 2.1 | D15: =D14*Project_Assumptions!$B$51 -> 2.1 | E15: =E14*Project_Assumptions!$B$51 -> 2.1 | F15: =F14*Project_Assumptions!$B$51 -> 2.1 | G15: =G14*Project_Assumptions!$B$51 -> 2.1 | H15: =H14*Project_Assumptions!$B$51 -> 2.1 | I15: =I14*Project_Assumptions!$B$51 -> 2.1 | J15: =J14*Project_Assumptions!$B$51 -> 2.1
A16: Tax Shield (£m) | B16: =B15*Inputs!$B$12 -> 0 | C16: =C15*Inputs!$B$12 -> 0.525 | D16: =D15*Inputs!$B$12 -> 0.525 | E16: =E15*Inputs!$B$12 -> 0.525 | F16: =F15*Inputs!$B$12 -> 0.525 | G16: =G15*Inputs!$B$12 -> 0.525 | H16: =H15*Inputs!$B$12 -> 0.525 | I16: =I15*Inputs!$B$12 -> 0.525 | J16: =J15*Inputs!$B$12 -> 0.525
A17: Discount Factor (r_d) | B17: =1 -> 1 | C17: =1/(1+Inputs!$B$9)^1 -> 0.9596929 | D17: =1/(1+Inputs!$B$9)^2 -> 0.92101046 | E17: =1/(1+Inputs!$B$9)^3 -> 0.8838872 | F17: =1/(1+Inputs!$B$9)^4 -> 0.84826027 | G17: =1/(1+Inputs!$B$9)^5 -> 0.81406935 | H17: =1/(1+Inputs!$B$9)^6 -> 0.78125658 | I17: =1/(1+Inputs!$B$9)^7 -> 0.74976639 | J17: =1/(1+Inputs!$B$9)^8 -> 0.71954548
A18: PV of Tax Shield (£m) | B18: =B16*B17 -> 0 | C18: =C16*C17 -> 0.50383877 | D18: =D16*D17 -> 0.48353049 | E18: =E16*E17 -> 0.46404078 | F18: =F16*F17 -> 0.44533664 | G18: =G16*G17 -> 0.42738641 | H18: =H16*H17 -> 0.4101597 | I18: =I16*I17 -> 0.39362735 | J18: =J16*J17 -> 0.37776138
A20: PV of Tax Shields (£m) | B20: =SUM(B18:J18) -> 3.5056815
A23: C. ADJUSTED PRESENT VALUE (£m)
A25: Base-Case Project PV (£m) | B25: =B10 -> 905.21174
A26: Add: PV of Tax Shields (£m) | B26: =B20 -> 3.5056815
A28: ADJUSTED PRESENT VALUE (APV) (£m) | B28: =B25+B26 -> 908.71742
A29: WACC (for base case) | B29: =Inputs!B7 -> 0.084
A30: Cost of Debt r_d (£m) | B30: =Inputs!B9 -> 0.042
A31: Tax Rate | B31: =Inputs!B12 -> 0.25
A32: Project Debt (£m) | B32: =Project_Assumptions!$B$50*Project_Assumptions!$B$17 -> 52.5
A33: Project Debt Interest Rate (£m) | B33: =Project_Assumptions!B51 -> 0.04

Sheet Val_FCFE
A1: VALUATION: FLOW TO EQUITY (FCFE) METHOD (£m)
A2: Method: Discounts equity cash flows (FCFF - After-Tax Interest + Net Debt Issuance) at Cost of Equity to get Equity Value (£m)
A4: Year | B4: 0 | C4: 1 | D4: 2 | E4: 3 | F4: 4 | G4: 5 | H4: 6 | I4: 7 | J4: 8
A5: A. FREE CASH FLOW TO FIRM (£m)
A6: FCFF (£m) | B6: =Project_FCF!B18-Project_FCF!B17 -> -350 | C6: =Project_FCF!C18-Project_FCF!C17 -> 32.575 | D6: =Project_FCF!D18-Project_FCF!D17 -> 58.199 | E6: =Project_FCF!E18-Project_FCF!E17 -> 61.61668 | F6: =Project_FCF!F18-Project_FCF!F17 -> 65.273598 | G6: =Project_FCF!G18-Project_FCF!G17 -> 68.33387 | H6: =Project_FCF!H18-Project_FCF!H17 -> 70.692224 | I6: =Project_FCF!I18-Project_FCF!I17 -> 72.53011 | J6: =Project_FCF!J18-Project_FCF!J17 -> 106.87809
A9: B. FINANCING ADJUSTMENTS
A10: Interest on Project Debt (£m) | B10: 0 | C10: =Project_Assumptions!$B$50*Project_Assumptions!$B$17*Project_Assumptions!$B$51 -> 2.1 | D10: =Project_Assumptions!$B$50*Project_Assumptions!$B$17*Project_Assumptions!$B$51 -> 2.1 | E10: =Project_Assumptions!$B$50*Project_Assumptions!$B$17*Project_Assumptions!$B$51 -> 2.1 | F10: =Project_Assumptions!$B$50*Project_Assumptions!$B$17*Project_Assumptions!$B$51 -> 2.1 | G10: =Project_Assumptions!$B$50*Project_Assumptions!$B$17*Project_Assumptions!$B$51 -> 2.1 | H10: =Project_Assumptions!$B$50*Project_Assumptions!$B$17*Project_Assumptions!$B$51 -> 2.1 | I10: =Project_Assumptions!$B$50*Project_Assumptions!$B$17*Project_Assumptions!$B$51 -> 2.1 | J10: =Project_Assumptions!$B$50*Project_Assumptions!$B$17*Project_Assumptions!$B$51 -> 2.1
A11: After-Tax Interest (£m) | B11: =B10*(1-Inputs!$B$12) -> 0 | C11: =C10*(1-Inputs!$B$12) -> 1.575 | D11: =D10*(1-Inputs!$B$12) -> 1.575 | E11: =E10*(1-Inputs!$B$12) -> 1.575 | F11: =F10*(1-Inputs!$B$12) -> 1.575 | G11: =G10*(1-Inputs!$B$12) -> 1.575 | H11: =H10*(1-Inputs!$B$12) -> 1.575 | I11: =I10*(1-Inputs!$B$12) -> 1.575 | J11: =J10*(1-Inputs!$B$12) -> 1.575
A12: Net Debt Issuance/(Repayment) (£m) | B12: =Project_Assumptions!$B$50*Project_Assumptions!$B$17 -> 52.5 | C12: 0 | D12: 0 | E12: 0 | F12: 0 | G12: 0 | H12: 0 | I12: 0 | J12: 0
A15: C. FREE CASH FLOW TO EQUITY (£m)
A16: FCFE (£m) | B16: =B6-B11+B12 -> -297.5 | C16: =C6-C11+C12 -> 31 | D16: =D6-D11+D12 -> 56.624 | E16: =E6-E11+E12 -> 60.04168 | F16: =F6-F11+F12 -> 63.698598 | G16: =G6-G11+G12 -> 66.75887 | H16: =H6-H11+H12 -> 69.117224 | I16: =I6-I11+I12 -> 70.95511 | J16: =J6-J11+J12 -> 105.30309
A17: Terminal Value (£m) | B17: =Project_FCF!B17 -> 0 | C17: =Project_FCF!C17 -> 0 | D17: =Project_FCF!D17 -> 0 | E17: =Project_FCF!E17 -> 0 | F17: =Project_FCF!F17 -> 0 | G17: =Project_FCF!G17 -> 0 | H17: =Project_FCF!H17 -> 0 | I17: =Project_FCF!I17 -> 0 | J17: =Project_FCF!J17 -> 1703.3696
A18: Total FCFE (£m) | B18: =B16+B17 -> -297.5 | C18: =C16+C17 -> 31 | D18: =D16+D17 -> 56.624 | E18: =E16+E17 -> 60.04168 | F18: =F16+F17 -> 63.698598 | G18: =G16+G17 -> 66.75887 | H18: =H16+H17 -> 69.117224 | I18: =I16+I17 -> 70.95511 | J18: =J16+J17 -> 1808.6727
A21: D. DISCOUNTING AT COST OF EQUITY (£m)
A22: Discount Factor (r_e) | B22: =1 -> 1 | C22: =1/(1+Inputs!$B$8)^1 -> 0.90826521 | D22: =1/(1+Inputs!$B$8)^2 -> 0.8249457 | E22: =1/(1+Inputs!$B$8)^3 -> 0.74926948 | F22: =1/(1+Inputs!$B$8)^4 -> 0.6805354 | G22: =1/(1+Inputs!$B$8)^5 -> 0.61810663 | H22: =1/(1+Inputs!$B$8)^6 -> 0.56140475 | I22: =1/(1+Inputs!$B$8)^7 -> 0.50990441 | J22: =1/(1+Inputs!$B$8)^8 -> 0.46312844
A23: PV of FCFE (£m) | B23: =B18*B22 -> -297.5 | C23: =C18*C22 -> 28.156222 | D23: =D18*D22 -> 46.711725 | E23: =E18*E22 -> 44.987398 | F23: =F18*F22 -> 43.349151 | G23: =G18*G22 -> 41.2641 | H23: =H18*H22 -> 38.802738 | I23: =I18*I22 -> 36.180324 | J23: =J18*J22 -> 837.64778
A26: E. EQUITY VALUE (£m)
A28: EQUITY VALUE (£m) | B28: =SUM(B23:J23) -> 819.59943
A31: F. ASSUMPTIONS USED
A32: Cost of Equity, r_e (£m) | B32: =Inputs!B8 -> 0.101
A33: Tax Rate | B33: =Inputs!B12 -> 0.25
A34: Project Debt (£m) | B34: =Project_Assumptions!$B$50*Project_Assumptions!$B$17 -> 52.5
A35: Project Debt Interest Rate (£m) | B35: =Project_Assumptions!B51 -> 0.04

Sheet Sensitivity
A1: SENSITIVITY ANALYSIS
A3: A. One-way Sensitivity: NPV vs WACC (£m)
B5: WACC | C5: NPV (£m)
B6: 0.06 | C6: =NPV(B6,Project_FCF!C18:J18)+Project_FCF!B18 -> 1120.8722
B7: 0.07 | C7: =NPV(B7,Project_FCF!C18:J18)+Project_FCF!B18 -> 1025.9468
B8: 0.08 | C8: =NPV(B8,Project_FCF!C18:J18)+Project_FCF!B18 -> 938.34577
B9: 0.084 | C9: =NPV(B9,Project_FCF!C18:J18)+Project_FCF!B18 -> 905.21174
B10: 0.09 | C10: =NPV(B10,Project_FCF!C18:J18)+Project_FCF!B18 -> 857.43364
B11: 0.1 | C11: =NPV(B11,Project_FCF!C18:J18)+Project_FCF!B18 -> 782.63547
B12: 0.11 | C12: =NPV(B12,Project_FCF!C18:J18)+Project_FCF!B18 -> 713.43076
B13: 0.12 | C13: =NPV(B13,Project_FCF!C18:J18)+Project_FCF!B18 -> 649.34779
A15: B. One-way Sensitivity: NPV vs Terminal Growth Rate g (£m)
B17: g | C17: NPV (£m)
B18: 0 | C18: =NPV(Inputs!$B$7,Project_FCF!C18:I18,(Project_FCF!J18-Project_FCF!J17)+(Project_FCF!J18-Project_FCF!J17)*(1+B18)/(Inputs!$B$7-B18))+Project_FCF!B18 -> 679.13574
B19: 0.01 | C19: =NPV(Inputs!$B$7,Project_FCF!C18:I18,(Project_FCF!J18-Project_FCF!J17)+(Project_FCF!J18-Project_FCF!J17)*(1+B19)/(Inputs!$B$7-B19))+Project_FCF!B18 -> 776.89833
B20: 0.02 | C20: =NPV(Inputs!$B$7,Project_FCF!C18:I18,(Project_FCF!J18-Project_FCF!J17)+(Project_FCF!J18-Project_FCF!J17)*(1+B20)/(Inputs!$B$7-B20))+Project_FCF!B18 -> 905.21174
B21: 0.03 | C21: =NPV(Inputs!$B$7,Project_FCF!C18:I18,(Project_FCF!J18-Project_FCF!J17)+(Project_FCF!J18-Project_FCF!J17)*(1+B21)/(Inputs!$B$7-B21))+Project_FCF!B18 -> 1081.0486
B22: 0.04 | C22: =NPV(Inputs!$B$7,Project_FCF!C18:I18,(Project_FCF!J18-Project_FCF!J17)+(Project_FCF!J18-Project_FCF!J17)*(1+B22)/(Inputs!$B$7-B22))+Project_FCF!B18 -> 1336.8114

Sheet Scenarios
A1: SCENARIO ANALYSIS (High-level, revenue-proportional FCFF) (£m)
B3: Scenario | C3: Year 1 Revenue | D3: Scale vs Base | E3: NPV (£m) | G3: FCFF1 | H3: FCFF2 | I3: FCFF3 | J3: FCFF4 | K3: FCFF5 | L3: FCFF6 | M3: FCFF7 | N3: FCFF8
B4: Pessimistic | C4: 140 | D4: =C4/Project_Assumptions!$B$20 -> 0.875 | E4: =NPV(Inputs!$B$7,G4:N4)+Project_FCF!B18 -> 748.31027 | G4: =Project_FCF!C18*$D4 -> 28.503125 | H4: =Project_FCF!D18*$D4 -> 50.924125 | I4: =Project_FCF!E18*$D4 -> 53.914595 | J4: =Project_FCF!F18*$D4 -> 57.114398 | K4: =Project_FCF!G18*$D4 -> 59.792136 | L4: =Project_FCF!H18*$D4 -> 61.855696 | M4: =Project_FCF!I18*$D4 -> 63.463846 | N4: =Project_FCF!J18*$D4 -> 1583.9668
B5: Base | C5: 160 | D5: =C5/Project_Assumptions!$B$20 -> 1 | E5: =NPV(Inputs!$B$7,G5:N5)+Project_FCF!B18 -> 905.21174 | G5: =Project_FCF!C18*$D5 -> 32.575 | H5: =Project_FCF!D18*$D5 -> 58.199 | I5: =Project_FCF!E18*$D5 -> 61.61668 | J5: =Project_FCF!F18*$D5 -> 65.273598 | K5: =Project_FCF!G18*$D5 -> 68.33387 | L5: =Project_FCF!H18*$D5 -> 70.692224 | M5: =Project_FCF!I18*$D5 -> 72.53011 | N5: =Project_FCF!J18*$D5 -> 1810.2477
B6: Optimistic | C6: 190 | D6: =C6/Project_Assumptions!$B$20 -> 1.1875 | E6: =NPV(Inputs!$B$7,G6:N6)+Project_FCF!B18 -> 1140.5639 | G6: =Project_FCF!C18*$D6 -> 38.682813 | H6: =Project_FCF!D18*$D6 -> 69.111313 | I6: =Project_FCF!E18*$D6 -> 73.169808 | J6: =Project_FCF!F18*$D6 -> 77.512397 | K6: =Project_FCF!G18*$D6 -> 81.14647 | L6: =Project_FCF!H18*$D6 -> 83.947016 | M6: =Project_FCF!I18*$D6 -> 86.129506 | N6: =Project_FCF!J18*$D6 -> 2149.6692

Sheet BreakEven
A1: BREAK-EVEN ANALYSIS – Goal Seek on Year 1 Revenue (£m)
A3: Base Year 1 Revenue (from Project_Assumptions) (£m) | B3: =Project_Assumptions!$B$20 -> 160
A4: Year 1 Revenue (input for Goal Seek) (£m) | B4: 44.613987
A5: Scale vs Base | B5: =B4/B3 -> 0.27883742
A7: Scaled FCFF used for NPV (do not edit formulas below) (£m)
B8: FCFF1 (£m) | C8: FCFF2 | D8: FCFF3 | E8: FCFF4 | F8: FCFF5 | G8: FCFF6 | H8: FCFF7 | I8: FCFF8
B9: =Project_FCF!C18*$B$5 -> 9.0831289 | C9: =Project_FCF!D18*$B$5 -> 16.228059 | D9: =Project_FCF!E18*$B$5 -> 17.181036 | E9: =Project_FCF!F18*$B$5 -> 18.200721 | F9: =Project_FCF!G18*$B$5 -> 19.05404 | G9: =Project_FCF!H18*$B$5 -> 19.711637 | H9: =Project_FCF!I18*$B$5 -> 20.224109 | I9: =Project_FCF!J18*$B$5 -> 504.7648
A11: NPV at this Year 1 Revenue (£m) | B11: =NPV(Inputs!$B$7,B9:I9)+Project_FCF!B18 -> 0
A13: Instruction:
A14: Use Data → What-If Analysis → Goal Seek:
A15: Set cell B11 to value 0, by changing cell B4. (£m)

Sheet MonteCarlo
A1: MONTE CARLO SIMULATION – WACC UNCERTAINTY
A3: Base WACC (from Inputs) | B3: =Inputs!$B$7 -> 0.084 | D3: SUMMARY (NPV distribution)
A4: WACC min | B4: =B3-0.02 -> 0.064 | D4: Mean NPV | E4: =AVERAGE(C9:C10008) -> 909.22158
A5: WACC max | B5: =B3+0.02 -> 0.104 | D5: Std Dev NPV | E5: =_xlfn.STDEV.S(C9:C10008) -> 95.338054
A6: # Simulations | B6: 10000 | D6: Prob(NPV<0) | E6: =COUNTIF(C9:C10008,"<0")/ROWS(C9:C10008) -> 0
A8: Sim # | B8: Random WACC | C8: NPV (£m)
A9: 1 | B9: =$B$4+RAND()*($B$5-$B$4) -> 0.10370193 | C9: =NPV(B9,Project_FCF!C18:J18)+Project_FCF!B18 -> 756.3904
A10: 2 | B10: =$B$4+RAND()*($B$5-$B$4) -> 0.083282747 | C10: =NPV(B10,Project_FCF!C18:J18)+Project_FCF!B18 -> 911.07612
A11: 3 | B11: =$B$4+RAND()*($B$5-$B$4) -> 0.073653395 | C11: =NPV(B11,Project_FCF!C18:J18)+Project_FCF!B18 -> 993.12843
A12: 4 | B12: =$B$4+RAND()*($B$5-$B$4) -> 0.081999428 | C12: =NPV(B12,Project_FCF!C18:J18)+Project_FCF!B18 -> 921.6522
A13: 5 | B13: =$B$4+RAND()*($B$5-$B$4) -> 0.069671244 | C13: =NPV(B13,Project_FCF!C18:J18)+Project_FCF!B18 -> 1028.9474
A14: 6 | B14: =$B$4+RAND()*($B$5-$B$4) -> 0.074898218 | C14: =NPV(B14,Project_FCF!C18:J18)+Project_FCF!B18 -> 982.16364
A15: 7 | B15: =$B$4+RAND()*($B$5-$B$4) -> 0.082341722 | C15: =NPV(B15,Project_FCF!C18:J18)+Project_FCF!B18 -> 918.82077
A16: 8 | B16: =$B$4+RAND()*($B$5-$B$4) -> 0.082362282 | C16: =NPV(B16,Project_FCF!C18:J18)+Project_FCF!B18 -> 918.65094
A17: 9 | B17: =$B$4+RAND()*($B$5-$B$4) -> 0.082027806 | C17: =NPV(B17,Project_FCF!C18:J18)+Project_FCF!B18 -> 921.41717
A18: 10 | B18: =$B$4+RAND()*($B$5-$B$4) -> 0.073588473 | C18: =NPV(B18,Project_FCF!C18:J18)+Project_FCF!B18 -> 993.70328
A19: 11 | B19: =$B$4+RAND()*($B$5-$B$4) -> 0.085433718 | C19: =NPV(B19,Project_FCF!C18:J18)+Project_FCF!B18 -> 893.5886
A20: 12 | B20: =$B$4+RAND()*($B$5-$B$4) -> 0.076394199 | C20: =NPV(B20,Project_FCF!C18:J18)+Project_FCF!B18 -> 969.12999
A21: 13 | B21: =$B$4+RAND()*($B$5-$B$4) -> 0.098026329 | C21: =NPV(B21,Project_FCF!C18:J18)+Project_FCF!B18 -> 796.9394
A22: 14 | B22: =$B$4+RAND()*($B$5-$B$4) -> 0.084393949 | C22: =NPV(B22,Project_FCF!C18:J18)+Project_FCF!B18 -> 902.00487
A23: 15 | B23: =$B$4+RAND()*($B$5-$B$4) -> 0.095307675 | C23: =NPV(B23,Project_FCF!C18:J18)+Project_FCF!B18 -> 817.00612
A24: 16 | B24: =$B$4+RAND()*($B$5-$B$4) -> 0.07296459 | C24: =NPV(B24,Project_FCF!C18:J18)+Project_FCF!B18 -> 999.2427
A25: 17 | B25: =$B$4+RAND()*($B$5-$B$4) -> 0.07580778 | C25: =NPV(B25,Project_FCF!C18:J18)+Project_FCF!B18 -> 974.2206
A26: 18 | B26: =$B$4+RAND()*($B$5-$B$4) -> 0.064598832 | C26: =NPV(B26,Project_FCF!C18:J18)+Project_FCF!B18 -> 1076.2647
A27: 19 | B27: =$B$4+RAND()*($B$5-$B$4) -> 0.081171181 | C27: =NPV(B27,Project_FCF!C18:J18)+Project_FCF!B18 -> 928.53527
A28: 20 | B28: =$B$4+RAND()*($B$5-$B$4) -> 0.099019442 | C28: =NPV(B28,Project_FCF!C18:J18)+Project_FCF!B18 -> 789.71449
A29: 21 | B29: =$B$4+RAND()*($B$5-$B$4) -> 0.087100098 | C29: =NPV(B29,Project_FCF!C18:J18)+Project_FCF!B18 -> 880.24358
A30: 22 | B30: =$B$4+RAND()*($B$5-$B$4) -> 0.068069006 | C30: =NPV(B30,Project_FCF!C18:J18)+Project_FCF!B18 -> 1043.6854
A31: 23 | B31: =$B$4+RAND()*($B$5-$B$4) -> 0.066024331 | C31: =NPV(B31,Project_FCF!C18:J18)+Project_FCF!B18 -> 1062.7712
A32: 24 | B32: =$B$4+RAND()*($B$5-$B$4) -> 0.094600988 | C32: =NPV(B32,Project_FCF!C18:J18)+Project_FCF!B18 -> 822.29237
A33: 25 | B33: =$B$4+RAND()*($B$5-$B$4) -> 0.075527572 | C33: =NPV(B33,Project_FCF!C18:J18)+Project_FCF!B18 -> 976.66146
A34: 26 | B34: =$B$4+RAND()*($B$5-$B$4) -> 0.073291492 | C34: =NPV(B34,Project_FCF!C18:J18)+Project_FCF!B18 -> 996.33671
A35: 27 | B35: =$B$4+RAND()*($B$5-$B$4) -> 0.085296192 | C35: =NPV(B35,Project_FCF!C18:J18)+Project_FCF!B18 -> 894.69783
A36: 28 | B36: =$B$4+RAND()*($B$5-$B$4) -> 0.070011811 | C36: =NPV(B36,Project_FCF!C18:J18)+Project_FCF!B18 -> 1025.8391
A37: 29 | B37: =$B$4+RAND()*($B$5-$B$4) -> 0.087837463 | C37: =NPV(B37,Project_FCF!C18:J18)+Project_FCF!B18 -> 874.39419
A38: 30 | B38: =$B$4+RAND()*($B$5-$B$4) -> 0.079377794 | C38: =NPV(B38,Project_FCF!C18:J18)+Project_FCF!B18 -> 943.59497
A39: 31 | B39: =$B$4+RAND()*($B$5-$B$4) -> 0.081114355 | C39: =NPV(B39,Project_FCF!C18:J18)+Project_FCF!B18 -> 929.00918
A40: 32 | B40: =$B$4+RAND()*($B$5-$B$4) -> 0.089493201 | C40: =NPV(B40,Project_FCF!C18:J18)+Project_FCF!B18 -> 861.38257
A41: 33 | B41: =$B$4+RAND()*($B$5-$B$4) -> 0.092652322 | C41: =NPV(B41,Project_FCF!C18:J18)+Project_FCF!B18 -> 837.02131
A42: 34 | B42: =$B$4+RAND()*($B$5-$B$4) -> 0.087832639 | C42: =NPV(B42,Project_FCF!C18:J18)+Project_FCF!B18 -> 874.43235
...

Sheet Appendix
A1: Capital Structure Ratio Trends (Part 2)
A2: Ratio | B2: FY 2020 | C2: FY 2021 | D2: FY 2022 | E2: FY 2023 | F2: FY 2024
A3: Debt / Assets (£m) | B3: =(Hist_Financials!B21+Hist_Financials!B22)/Hist_Financials!B18 -> 0.50393299 | C3: =(Hist_Financials!C21+Hist_Financials!C22)/Hist_Financials!C18 -> 0.46089569 | D3: =(Hist_Financials!D21+Hist_Financials!D22)/Hist_Financials!D18 -> 0.4387434 | E3: =(Hist_Financials!E21+Hist_Financials!E22)/Hist_Financials!E18 -> 0.4632266 | F3: =(Hist_Financials!F21+Hist_Financials!F22)/Hist_Financials!F18 -> 0.47281964
A4: Debt / Equity (£m) | B4: =IF(Hist_Financials!B20<=0,"",(Hist_Financials!B21+Hist_Financials!B22)/Hist_Financials!B20) -> 1.9887441 | C4: =IF(Hist_Financials!C20<=0,"",(Hist_Financials!C21+Hist_Financials!C22)/Hist_Financials!C20) -> 1.7467679 | D4: =IF(Hist_Financials!D20<=0,"",(Hist_Financials!D21+Hist_Financials!D22)/Hist_Financials!D20) -> 1.6840414 | E4: =IF(Hist_Financials!E20<=0,"",(Hist_Financials!E21+Hist_Financials!E22)/Hist_Financials!E20) -> 1.7756427 | F4: =IF(Hist_Financials!F20<=0,"",(Hist_Financials!F21+Hist_Financials!F22)/Hist_Financials!F20) -> 1.7813588
A5: Debt/Tangible Net Worth (£m) | B5: -5.8688811 | C5: -6.3124732 | D5: -6.7076117 | E5: -7.4333215 | F5: -7.8356402
A6: Interest Coverage | B6: =IF(Hist_Financials!B12=0,"",ABS(Hist_Financials!B11/Hist_Financials!B12)) -> 4.0299625 | C6: =IF(Hist_Financials!C12=0,"",ABS(Hist_Financials!C11/Hist_Financials!C12)) -> 7.8844538 | D6: =IF(Hist_Financials!D12=0,"",ABS(Hist_Financials!D11/Hist_Financials!D12)) -> 9.0520639 | E6: =IF(Hist_Financials!E12=0,"",ABS(Hist_Financials!E11/Hist_Financials!E12)) -> 5.9390991 | F6: =IF(Hist_Financials!F12=0,"",ABS(Hist_Financials!F11/Hist_Financials!F12)) -> 8.4041976
